// 簡単な例外処理をしてみよう
using System;

class Lesson1
{
    public static void Main()
    {
        // 例外が投げられる可能性のあるコード
        try
        {
            Console.WriteLine("Hello World");

            int number = 0;
            // 0で割り算できないためエラーが起きる
            // ここで処理が中断され、catchブロックに飛ぶ
            int answer = 100 / number;
            Console.WriteLine(answer);
        }
        // 例外が起きた場合の処理
        // Exception e の中に例外の詳細情報が格納されている
        catch(Exception e)
        {
            Console.WriteLine(e.Message);
        }
        // 例外発生の有無にかかわらず実行したいコード
        finally
        {
            Console.WriteLine("Hello C#");
        }
    }
}


