
// ログを出力のためにcatchし、再throwする。
void Rethrow()
{
    try
    {
        RaiseError();
    }
    catch (Exception ex)
    {
        Console.WriteLine($"Failed to {nameof(Rethrow)}. : {ex.Message}");
        // throw exとは書いてはいけない。StackTraceが消えるため。
        throw;
    }
}

// 別の例外に変換する
void Convert()
{
    try
    {
        RaiseError();
    }
    catch (Exception ex)
    {
        // catchしたExceptionはInnerExceptionにする。
        throw new OriginalException($"Original exception occurred", ex);
    }
}

// 独自のエラーハンドリングをする。
void ErrorHandleSelf()
{
    try
    {
        RaiseError();
    }
    catch (Exception ex)
    {
        // HandleErrorメソッドできちんと処理が行われることが前提。極力使わない。
        HandleError(ex);
    }
}

