More than 1 year has passed since last update.タイトルの通り、C#での例外をCatch句内でthrowした挙動を確認してみました。環境：Visual Studio2017，.net472実行結果知識の浅い自分は'throw'したらFinallyの実行順がどうなるのか…？
と思って確認した結果です。


